import asyncio

def set_global_exception():
    def handle_exception(loop, context):
        import sys
        sys.print_exception(context["exception"])
        sys.exit()
    loop = asyncio.get_event_loop()
    loop.set_exception_handler(handle_exception)